<?xml version="1.0"?>
<robot name="diff_drive" xmlns:xacro="http://www.ros.org/wiki/xacro">
  <!-- 車体要素 -->
  <link name="chassis">
    <collision>
      <origin xyz="-0 -0 0.5" rpy="0 0 0"/>
      <geometry>
        <box size="2.5 1 0.568726"/>
      </geometry>
    </collision>

    <visual>
      <origin xyz="-0 -0 0.5" rpy="0 0 0"/>
      <geometry>
        <box size="2.5 1 0.568726"/>
      </geometry>
      <material name="orange">
        <color rgba="1 0.5 0 1"/>
      </material>
    </visual>

    <inertial>
      <origin xyz="-0.151427 -0 0.5" rpy="0 0 0"/>
      <mass value="1.14395"/>
      <inertia
        ixx="0.126164"
        ixy="0.0"
        ixz="0.0"
        iyy="0.416519"
        iyz="0.0"
        izz="0.481014"/>
    </inertial>
  </link>
  <link name="front_camera">
    <visual>
      <origin xyz="0 0 0" rpy="0 0 0"/>
      <geometry>
        <box size="0.1 0.1 0.1"/>
      </geometry>
      <material name="blue">
        <color rgba="0 0 1 1"/>
      </material>
    </visual>
  </link>
<!-- END OF 車体要素 -->

<!-- 車輪要素 -->
  <!-- left wheel Link -->
  <link name="left_wheel">
    <collision>
      <geometry>
        <cylinder length="0.2" radius="0.3"/>
      </geometry>
    </collision>

    <visual>
      <geometry>
        <cylinder length="0.2" radius="0.3"/>
      </geometry>
      <material name="red">
        <color rgba="1 0 0 1"/>
      </material>
    </visual>

    <inertial>
      <mass value="20"/>
      <inertia ixx="0.145833"
               ixy="0.0"
               ixz="0.0"
               iyy="0.145833"
               iyz="0.0"
               izz="0.125"/>
    </inertial>
  </link>
  <!-- right wheel Link -->
  <link name="right_wheel">
    <collision>
      <geometry>
        <cylinder length="0.2" radius="0.3"/>
      </geometry>
    </collision>

    <visual>
      <geometry>
        <cylinder length="0.2" radius="0.3"/>
      </geometry>
      <material name="red"/>
    </visual>

    <inertial>
      <mass value="20"/>
      <inertia ixx="0.145833"
               ixy="0.0"
               ixz="0.0"
               iyy="0.145833"
               iyz="0.0"
               izz="0.125"/>
      </inertial>
  </link>
<!-- END OF 車輪要素 -->

<!-- 車輪ジョイント -->
  <joint name="left_wheel_joint" type="continuous">
    <origin xyz="0 0.625029 0.3" rpy="-1.5707 0 0"/>
    <parent link="chassis"/>
    <child link="left_wheel"/>
    <axis xyz="0 0 1"/>
    <dynamics damping="0.2"/>
  </joint>
  <joint name="right_wheel_joint" type="continuous">
    <origin xyz="0 -0.625029 0.3" rpy="-1.5707 0 0"/>
    <parent link="chassis"/>
    <child link="right_wheel"/>
    <axis xyz="0 0 1"/>
    <dynamics damping="0.2"/>
  </joint>
<!-- END OF 車輪ジョイント -->

<!-- キャスターのジョイント -->
  <joint name="caster_back_joint" type="fixed">
    <origin xyz="-0.957138 -0 0.2" rpy="0 0 0"/>
    <parent link="chassis"/>
    <child link="caster_back"/>
  </joint>
  <joint name="caster_front_joint" type="fixed">
    <origin xyz="0.957138 -0 0.2" rpy="0 0 0"/>
    <parent link="chassis"/>
    <child link="caster_front"/>
  </joint>
<!-- END OF キャスターのジョイント -->
  <joint name="front_camera_joint" type="fixed">
    <origin xyz="1.2 0 0.82" rpy="0 0 0"/>
    <parent link="chassis"/>
    <child link="front_camera"/>
  </joint>

<!-- キャスター要素 -->
  <link name="caster_back">
    <collision>
      <geometry>
        <sphere radius="0.2"/>
      </geometry>
    </collision>

    <visual>
      <geometry>
        <sphere radius="0.2"/>
      </geometry>
      <material name="white">
        <color rgba="1 1 1 1"/>
      </material>
    </visual>

    <inertial>
      <origin xyz="-0.957138 -0 0.2" rpy="0 0 0"/>
      <mass value="0.005"/>
      <inertia
        ixx="0.1"
        ixy="0.0"
        ixz="0.0"
        iyy="0.1"
        iyz="0.0"
        izz="0.1"/>
    </inertial>
  </link>
  <link name="caster_front">
    <collision>
      <geometry>
        <sphere radius="0.2"/>
      </geometry>
    </collision>

    <visual>
      <geometry>
        <sphere radius="0.2"/>
      </geometry>
      <material name="white"/>
    </visual>

    <inertial>
      <origin xyz="0.957138 -0 0.2" rpy="0 0 0"/>
      <mass value="0.005"/>
      <inertia
        ixx="0.1"
        ixy="0.0"
        ixz="0.0"
        iyy="0.1"
        iyz="0.0"
        izz="0.1"/>
    </inertial>
  </link>
<!-- END OF キャスター要素 -->


<!-- root : leg1 -->
  <!-- 直動棒 -->
  <link name="slideBar">
    <visual>
      <geometry>
        <box size="0.05 0.05 2"/>
      </geometry>
      <origin xyz="0 0 0"/>
      <material name="red"/>
    </visual>
    <inertial>
      <mass value="0.1"/>
      <inertia ixx="1.0" ixy="0.0" ixz="0.0" iyy="1.0" iyz="0.0" izz="1.0"/>
    </inertial>
  </link>
  <!-- 直動カートの関節 -->
  <link name="cart">
    <visual>
      <geometry><box size="0.2 0.2 0.01"/></geometry>
      <origin xyz="0 0 0"/>
    </visual>
    <inertial>
      <mass value="1"/>
      <inertia ixx="1.0" ixy="0.0" ixz="0.0" iyy="1.0" iyz="0.0" izz="1.0"/>
    </inertial>
  </link>
  <link name="cart_hinge">
    <collision>
      <geometry><box size="0.1 0.1 0.01"/></geometry>
      <origin xyz="0 0 0"/>
    </collision>
    <visual>
      <geometry><box size="0.1 0.1 0.01"/></geometry>
      <origin xyz="0 0 0"/>
      <material name="red"/>
    </visual>
    <inertial>
      <mass value="1"/>
      <inertia ixx="1.0" ixy="0.0" ixz="0.0" iyy="1.0" iyz="0.0" izz="1.0"/>
    </inertial>
  </link>

  <!-- カートの形状 -->
  <link name="cart_board">
    <collision>
      <geometry><box size="1.0 1.0 0.01"/></geometry>
      <origin xyz="0 0 0"/>
    </collision>
    <visual>
      <geometry><box size="1.0 1.0 0.01"/></geometry>
      <origin xyz="0 0 0"/>
      <material name="green">
        <color rgba="0 1 0 1"/>
      </material>
    </visual>
    <inertial>
      <mass value="1"/>
      <inertia ixx="1.0" ixy="0.0" ixz="0.0" iyy="1.0" iyz="0.0" izz="1.0"/>
    </inertial>
  </link>
  <link name="cart_left">
    <collision>
      <geometry><box size="0.5 1.0 0.01"/></geometry>
      <origin xyz="0 0 0"/>
    </collision>
    <visual>
      <geometry><box size="0.5 1.0 0.01"/></geometry>
      <origin xyz="0 0 0"/>
      <material name="green" />
    </visual>
    <inertial>
      <mass value="1"/>
      <inertia ixx="1.0" ixy="0.0" ixz="0.0" iyy="1.0" iyz="0.0" izz="1.0"/>
    </inertial>
  </link>
  <link name="cart_right">
    <collision>
      <geometry><box size="0.5 1.0 0.01"/></geometry>
      <origin xyz="0 0 0"/>
    </collision>
    <visual>
      <geometry><box size="0.5 1.0 0.01"/></geometry>
      <origin xyz="0 0 0"/>
      <material name="green" />
    </visual>
    <inertial>
      <mass value="1"/>
      <inertia ixx="1.0" ixy="0.0" ixz="0.0" iyy="1.0" iyz="0.0" izz="1.0"/>
    </inertial>
  </link>
  <joint name="cart_joint_left" type="fixed">
    <parent link="cart_board"/>
    <child link="cart_left"/>
    <origin xyz="0 0.5 0.25" rpy="0 1.57 1.57"/>
  </joint>
  <joint name="cart_joint_right" type="fixed">
    <parent link="cart_board"/>
    <child link="cart_right"/>
    <origin xyz="0 -0.5 0.25" rpy="0 1.57 1.57"/>
  </joint>
  <!-- END OF カートの形状 -->

  <!-- 直動端a  (root) -->
  <link name="leg1">
    <visual>
      <geometry><box size="0.2 0.2 0.2"/></geometry><origin xyz="0 0 0"/>
    </visual>
    <collision>
      <geometry><box size="0.2 0.2 0.2"/></geometry><origin xyz="0 0 0"/>
    </collision>
    <inertial>
      <mass value="1"/>
      <inertia ixx="1.0" ixy="0.0" ixz="0.0" iyy="1.0" iyz="0.0" izz="1.0"/>
    </inertial>
  </link>
  <!-- 直動端b -->
  <link name="leg2">
    <visual>
      <geometry><box size="0.2 0.2 0.2"/></geometry><origin xyz="0 0 0"/>
    </visual>
    <collision>
      <geometry><box size="0.2 0.2 0.2"/></geometry><origin xyz="0 0 0"/>
    </collision>
    <inertial>
      <mass value="1"/>
      <inertia ixx="1.0" ixy="0.0" ixz="0.0" iyy="1.0" iyz="0.0" izz="1.0"/>
    </inertial>
  </link>
  <!-- imu -->
  <link name="imu">
    <inertial>
      <mass value="0.1"/>
      <inertia ixx="1.0" ixy="0" ixz="0" iyy="1.0" iyz="0" izz="1.0"/>
    </inertial>
  </link>

  <!-- ジョイント -->
  <!-- 直動移動のパラメータ -->
  <joint name="slider_to_cart" type="prismatic">
    <!-- 軸の方向 -->
    <axis xyz="0 0 1"/>
    <origin xyz="-0.1 0.0 0.0"/>
    <parent link="slideBar"/>
    <child link="cart"/>
    <!-- 初期位置からの移動方向 (-0.5 <===> 0.5) -->
    <limit effort="1000.0" lower="-1" upper="1" velocity="30"/>
    <dynamics damping="0.0" friction="0.0"/>
  </joint>
  <!-- 移動用のカートと衝突ありのカートのジョイント -->
  <joint name="cart_to_cart_hinge" type="revolute">
    <parent link="cart"/>
    <child link="cart_hinge"/>
    <origin xyz="-0.1 0 0" rpy="0 0 -1.57"/>
    <limit effort="1000.0" lower="0.0" upper="0.548" velocity="0.5"/>
    <dynamics damping="0.0" friction="0.0"/>
  </joint>
  <joint name="cartreal_to_board" type="fixed">
    <parent link="cart_hinge"/>
    <child link="cart_board"/>
    <origin xyz="0 -0.5 0" rpy="0 0 1.57"/>
  </joint>

  <joint name="cart_to_imu" type="fixed">
    <origin xyz="0.0 0.0 0.0"/>
    <parent link="cart"/>
    <child link="imu"/>
    <dynamics damping="0.0" friction="0.0"/>
  </joint>

  <joint name="leg1_to_slider" type="fixed">
    <origin xyz="0.0 0.0 1"/>
    <parent link="leg1"/>
    <child link="slideBar"/>
    <dynamics damping="0.0" friction="0.0"/>
  </joint>

  <joint name="leg1_to_leg2" type="fixed">
    <origin xyz="0.0 0.0 2"/>
    <parent link="leg1"/>
    <child link="leg2"/>
    <dynamics damping="0.0" friction="0.0"/>
  </joint>

  <!-- 直動のつなぎ目 -->
  <joint name="chassis_to_leg1" type="fixed">
    <origin xyz="-1.55 0.0 0.14" rpy="0 0.5 0"/>
    <parent link="chassis"/>
    <child link="leg1"/>
    <dynamics damping="0.0" friction="0.0"/>
  </joint>


<!-- ignition -->
  <ros2_control name="IgnitionSystem" type="system">
    <hardware>
      <plugin>ign_ros2_control/IgnitionSystem</plugin>
    </hardware>

    <!-- 直動のros-control -->
    <joint name="slider_to_cart">
      <command_interface name="velocity">
        <param name="min">-2.0</param>
        <param name="max">2.0</param>
      </command_interface>
      <state_interface name="position"/>
      <state_interface name="velocity"/>
      <state_interface name="effort"/>
    </joint>
    <sensor name="cart_imu_sensor">
      <state_interface name="orientation.x"/>
      <state_interface name="orientation.y"/>
      <state_interface name="orientation.z"/>
      <state_interface name="orientation.w"/>
      <state_interface name="angular_velocity.x"/>
      <state_interface name="angular_velocity.y"/>
      <state_interface name="angular_velocity.z"/>
      <state_interface name="linear_acceleration.x"/>
      <state_interface name="linear_acceleration.y"/>
      <state_interface name="linear_acceleration.z"/>
    </sensor>

    <joint name="cart_to_cart_hinge">
      <command_interface name="velocity">
        <param name="min">-2.0</param>
        <param name="max">2.0</param>
      </command_interface>
      <state_interface name="position"/>
      <state_interface name="velocity"/>
      <state_interface name="effort"/>
    </joint>
    
    <!-- 車輪のros-control -->
    <joint name="left_wheel_joint">
      <command_interface name="velocity">
        <param name="min">-1</param>
        <param name="max">1</param>
      </command_interface>
      <state_interface name="position"/>
      <state_interface name="velocity"/>
    </joint>
    <joint name="right_wheel_joint">
      <command_interface name="velocity">
        <param name="min">-1</param>
        <param name="max">1</param>
      </command_interface>
      <state_interface name="position"/>
      <state_interface name="velocity"/>
    </joint>
  </ros2_control>
<!-- END OF Ignition SYSTEM -->


<!-- Gazebo -->
  <gazebo>
    <!-- Joint state publisher -->
    <plugin filename="ign_ros2_control-system" name="ign_ros2_control::IgnitionROS2ControlPlugin">
      <parameters>$(find ign_robot)/config/ign_robot_config.yaml</parameters>
    </plugin>

    <plugin
      filename="ignition-gazebo-imu-system"
      name="ignition::gazebo::systems::Imu">
    </plugin>

    <plugin
        filename="ignition-gazebo-scene-broadcaster-system"
        name="ignition::gazebo::systems::SceneBroadcaster">
    </plugin>

    <plugin filename="ignition-gazebo-sensors-system"
      name="ignition::gazebo::systems::Sensors">
      <render_engine>ogre2</render_engine>
    </plugin>
  </gazebo>

  <!-- imu publisher -->
  <gazebo reference="imu">
    <sensor name="cart_imu_sensor" type="imu">
      <always_on>1</always_on>
      <update_rate>10.0</update_rate>
      <visualize>true</visualize>
      <topic>imu</topic>
    </sensor>
  </gazebo>

  <!-- camera publisher -->
  <gazebo reference="front_camera">
    <sensor name="segmentation_camera" type="camera">
      <topic>image</topic>
      <pose>0 0 0 0 0 0</pose>
      <camera>
        <segmentation_type>instance</segmentation_type>
        <horizontal_fov>1.047</horizontal_fov>
        <image>
          <width>800</width>
          <height>600</height>
        </image>
        <clip>
          <near>0.1</near>
          <far>10</far>
        </clip>
      </camera>
      <always_on>1</always_on>
      <update_rate>30</update_rate>
    </sensor>
  </gazebo>

  <gazebo reference="leg1">
    <sensor name='gpu_lidar' type='gpu_lidar'>
      <pose>0 0 0 0 0 0</pose>
      <topic>lidar2</topic>
      <update_rate>10</update_rate>
      <lidar>
        <scan>
          <horizontal>
            <samples>640</samples>
            <resolution>1</resolution>
            <min_angle>-1.396263</min_angle>
            <max_angle>1.396263</max_angle>
          </horizontal>
          <vertical>
            <samples>1</samples>
            <resolution>1</resolution>
            <min_angle>0.0</min_angle>
            <max_angle>0.0</max_angle>
          </vertical>
        </scan>
        <range>
          <min>0.08</min>
          <max>10.0</max>
          <resolution>0.01</resolution>
        </range>
      </lidar>
      <alwaysOn>1</alwaysOn>
      <visualize>true</visualize>
    </sensor>
  </gazebo>
<!-- END OF GAZEBO -->


</robot>
